error: called `App::run()` without handling the returned `AppExit`
 --> tests/ui/unused_appexit/generic_fn.rs:9:16
  |
9 |     App::new().run();
  |     -----------^^^^^
  |     |
  |     help: handle the returned `AppExit`: `let _app_exit = App::new().run()`
  |
  = note: `App::run()` returns `AppExit`, which is used to determine whether the app exited successfully or not
  = help: consider logging a warning if the returned `AppExit` is an error
note: the lint level is defined here
 --> tests/ui/unused_appexit/generic_fn.rs:4:9
  |
4 | #![deny(bevy::unused_appexit)]
  |         ^^^^^^^^^^^^^^^^^^^^

error: aborting due to 1 previous error

